<?xml version="1.0" encoding="UTF-8"?>
<sdf version='1.9'>
  <world name='myrobot'>
    <physics name='1ms' type='ignored'>
      <max_step_size>0.001</max_step_size>
      <real_time_factor>1</real_time_factor>
      <real_time_update_rate>1000</real_time_update_rate>
    </physics>
    <plugin name='ignition::gazebo::systems::Physics' filename='ignition-gazebo-physics-system'/>
    <plugin name='ignition::gazebo::systems::UserCommands' filename='ignition-gazebo-user-commands-system'/>
    <plugin name='ignition::gazebo::systems::SceneBroadcaster' filename='ignition-gazebo-scene-broadcaster-system'/>
    <plugin name='ignition::gazebo::systems::Contact' filename='ignition-gazebo-contact-system'/>
    <plugin filename="libignition-gazebo-imu-system.so" name="ignition::gazebo::systems::Imu"></plugin>
    
    <plugin filename="libignition-gazebo-sensors-system.so" name="ignition::gazebo::systems::Sensors">
    <render_engine>ogre2</render_engine>
    </plugin>
    
    <gravity>0 0 -9.8</gravity>
    <magnetic_field>6e-06 2.3e-05 -4.2e-05</magnetic_field>
    <atmosphere type='adiabatic'/>
    <scene>
      <ambient>0.4 0.4 0.4 1</ambient>
      <background>0.7 0.7 0.7 1</background>
      <shadows>true</shadows>
    </scene>
    <model name='ground_plane'>
      <static>true</static>
      <link name='link'>
        <collision name='collision'>
          <geometry>
            <plane>
              <normal>0 0 1</normal>
              <size>100 100</size>
            </plane>
          </geometry>
          <surface>
            <friction>
              <ode/>
            </friction>
            <bounce/>
            <contact/>
          </surface>
        </collision>
        <visual name='visual'>
          <geometry>
            <plane>
              <normal>0 0 1</normal>
              <size>100 100</size>
            </plane>
          </geometry>
          <material>
            <ambient>0.8 0.8 0.8 1</ambient>
            <diffuse>0.8 0.8 0.8 1</diffuse>
            <specular>0.8 0.8 0.8 1</specular>
          </material>
        </visual>
        <pose>0 0 0 0 -0 0</pose>
        <inertial>
          <pose>0 0 0 0 -0 0</pose>
          <mass>1</mass>
          <inertia>
            <ixx>1</ixx>
            <ixy>0</ixy>
            <ixz>0</ixz>
            <iyy>1</iyy>
            <iyz>0</iyz>
            <izz>1</izz>
          </inertia>
        </inertial>
        <enable_wind>false</enable_wind>
      </link>
      <pose>0 0 0 0 -0 0</pose>
      <self_collide>false</self_collide>
    </model>

    <model name='little_car' canonical_link='chassis'>
      <pose relative_to='world'>0 0 0 0 0 0</pose>
      <link name='chassis'>
        <pose relative_to='__model__'>0.5 0 0.4 0 0 0</pose>
        <inertial> <!--inertial properties of the link mass, inertia matix-->
            <mass>1.14395</mass>
            <inertia>
              <ixx>0.095329</ixx>
              <ixy>0</ixy>
              <ixz>0</ixz>
              <iyy>0.381317</iyy>
              <iyz>0</iyz>
              <izz>0.476646</izz>
            </inertia>
          </inertial>
          <visual name='visual'>
            <geometry>
              <box>
                <size>2.0 1.0 0.5</size>
              </box>
            </geometry>
            <!--let's add color to our link-->
            <material>
              <ambient>0.0 0.0 1.0 1</ambient>
              <diffuse>0.0 0.0 1.0 1</diffuse>
              <specular>0.0 0.0 1.0 1</specular>
            </material>
          </visual>
          <collision name='collision'>
            <geometry>
              <box>
                <size>2.0 1.0 0.5</size>
              </box>
            </geometry>
          </collision>
          <sensor name="imu_sensor" type="imu">
            <always_on>1</always_on>
            <update_rate>1</update_rate>
            <visualize>true</visualize>
            <topic>imu</topic>
          </sensor>
          <sensor name='gpu_lidar' type='gpu_lidar'>"
            <pose relative_to='chassis'>1.0 0 0 0 0 0</pose>
            <topic>lidar</topic>
            <update_rate>10</update_rate>
            <ray>
            <scan>
              <horizontal>
                <samples>640</samples>
                <resolution>1</resolution>
                <min_angle>-1.396263</min_angle>
                <max_angle>1.396263</max_angle>
              </horizontal>
              <vertical>
                <samples>1</samples>
                <resolution>0.01</resolution>
                <min_angle>0</min_angle>
                <max_angle>0</max_angle>
              </vertical>
            </scan>
            <range>
                <min>0.08</min>
                <max>10.0</max>
                <resolution>0.01</resolution>
            </range>
          </ray>
            <always_on>1</always_on>
            <visualize>true</visualize>
          </sensor>

          <sensor name='camera' type='camera'>
          <pose>1 0 0.5 0 -0 0</pose>
          <topic>camera</topic>
          <update_rate>30</update_rate>
          <enable_metrics>false</enable_metrics>
          <camera name='__default__'>
            <pose>0 0 0 0 -0 0</pose>
            <horizontal_fov>1.0469999999999999</horizontal_fov>
            <image>
              <width>640</width>
              <height>480</height>
              <format>RGB_INT8</format>
              <anti_aliasing>4</anti_aliasing>
            </image>
          <clip>
            <near>0.10000000000000001</near>
            <far>100</far>
          </clip>
          <save enabled='false'>
            <path>__default__</path>
          </save>
          <visibility_mask>4294967295</visibility_mask>
          <noise>
              <type>none</type>
              <mean>0</mean>
              <stddev>0</stddev>
          </noise>
          <distortion>
            <k1>0</k1>
            <k2>0</k2>
            <k3>0</k3>
            <p1>0</p1>
            <p2>0</p2>
            <center>0.5 0.5</center>
          </distortion>
          <lens>
            <type>stereographic</type>
            <scale_to_hfov>true</scale_to_hfov>
            <cutoff_angle>1.5708</cutoff_angle>
            <env_texture_size>256</env_texture_size>
          </lens>
        </camera>
        </sensor>
        
        </link>
        <link name='left_wheel'>
          <pose relative_to="chassis">-0.5 0.6 0 -1.5707 0 0</pose>
          <inertial>
            <mass>1</mass>
            <inertia>
              <ixx>0.043333</ixx>
              <ixy>0</ixy>
              <ixz>0</ixz>
              <iyy>0.043333</iyy>
              <iyz>0</iyz>
              <izz>0.08</izz>
              </inertia>
            </inertial>
            <visual name='visual'>
              <geometry>
                <cylinder>
                  <radius>0.4</radius>
                  <length>0.2</length>
                </cylinder>
              </geometry>
              <material> 
                <ambient>0.0 0.0 1.0 1</ambient>
                <diffuse>0.0 0.0 1.0 1</diffuse>
                <specular>0.0 0.0 1.0 1</specular>
              </material>
            </visual>
            <collision name='collision'>
              <geometry>
                <cylinder>
                  <radius>0.4</radius>
                  <length>0.2</length>
                </cylinder>
              </geometry>
            </collision>
        </link>
        <link name='right_wheel'>
          <pose relative_to="chassis">-0.5 -0.6 0 -1.5707 0 0</pose>
          <inertial>
            <mass>1</mass>
            <inertia>
              <ixx>0.043333</ixx>
              <ixy>0</ixy>
              <ixz>0</ixz>
              <iyy>0.043333</iyy>
              <iyz>0</iyz>
              <izz>0.08</izz>
              </inertia>
            </inertial>
            <visual name='visual'>
              <geometry>
                <cylinder>
                  <radius>0.4</radius>
                  <length>0.2</length>
                </cylinder>
              </geometry>
              <material> 
                <ambient>0.0 0.0 1.0 1</ambient>
                <diffuse>0.0 0.0 1.0 1</diffuse>
                <specular>0.0 0.0 1.0 1</specular>
              </material>
            </visual>
            <collision name='collision'>
              <geometry>
                <cylinder>
                  <radius>0.4</radius>
                  <length>0.2</length>
                </cylinder>
              </geometry>
            </collision>
        </link>
        <frame name="caster_frame" attached_to='chassis'>
          <pose>0.8 0 -0.2 0 0 0</pose>
        </frame>
        <link name='caster'>
          <pose relative_to='caster_frame'/>
            <inertial>
              <mass>1</mass>
              <inertia>
                <ixx>0.016</ixx>
                <ixy>0</ixy>
                <ixz>0</ixz>
                <iyy>0.016</iyy>
                <iyz>0</iyz>
                <izz>0.016</izz>
              </inertia>
            </inertial>
            <visual name='visual'>
              <geometry>
                <sphere>
                  <radius>0.2</radius>
                </sphere>
              </geometry>
              <material>
                <ambient>0.0 1 0.0 1</ambient>
                <diffuse>0.0 1 0.0 1</diffuse>
                <specular>0.0 1 0.0 1</specular>
              </material>
            </visual>
            <collision name='collision'>
              <geometry>
                <sphere>
                  <radius>0.2</radius>
                </sphere>
              </geometry>
            </collision>
        </link>
        <!--轮子关节-->
        <joint name='left_wheel_joint' type='revolute'>
          <pose relative_to='left_wheel'/>
          <parent>chassis</parent>
          <child>left_wheel</child>
          <axis>
            <xyz expressed_in='__model__'>0 1 0</xyz>
            <limit>
              <lower>-1.79769e+308</lower>
              <upper>1.79769e+308</upper>
            </limit>
          </axis>
        </joint>
        <joint name='right_wheel_joint' type='revolute'>
          <pose relative_to='right_wheel'/>
          <parent>chassis</parent>
          <child>right_wheel</child>
          <axis>
            <xyz expressed_in='__model__'>0 1 0</xyz>
            <limit>
              <lower>-1.79769e+308</lower>
              <upper>1.79769e+308</upper>
            </limit>
          </axis>
        </joint>
        <!--球轮关节-->
        <joint name='caster_wheel' type='ball'>
          <parent>chassis</parent>
          <child>caster</child>
        </joint>
        <plugin
          filename="libignition-gazebo-diff-drive-system.so"
          name="ignition::gazebo::systems::DiffDrive">
          <left_joint>left_wheel_joint</left_joint>
          <right_joint>right_wheel_joint</right_joint>
          <wheel_separation>1.2</wheel_separation>
          <wheel_radius>0.4</wheel_radius>
          <odom_publish_frequency>1</odom_publish_frequency>
          <topic>cmd_vel</topic>
        </plugin>
    </model>

    <light name='sun' type='directional'>
      <pose>0 0 10 0 -0 0</pose>
      <cast_shadows>true</cast_shadows>
      <intensity>1</intensity>
      <direction>-0.5 0.1 -0.9</direction>
      <diffuse>0.8 0.8 0.8 1</diffuse>
      <specular>0.2 0.2 0.2 1</specular>
      <attenuation>
        <range>1000</range>
        <linear>0.01</linear>
        <constant>0.90000000000000002</constant>
        <quadratic>0.001</quadratic>
      </attenuation>
      <spot>
        <inner_angle>0</inner_angle>
        <outer_angle>0</outer_angle>
        <falloff>0</falloff>
      </spot>
    </light>
  </world>
</sdf>