<?xml version="1.0" encoding="utf-8"?>
<!-- This URDF was automatically created by SolidWorks to URDF Exporter! Originally created by Stephen Brawner (brawner@gmail.com) 
     Commit Version: 1.6.0-4-g7f85cfe  Build Version: 1.6.7995.38578
     For more information, please see http://wiki.ros.org/sw_urdf_exporter -->
<robot
  name="hero_description">
  <link
    name="base_link">
    <inertial>
      <origin
        xyz="2.7756E-16 -1.0408E-17 -0.0025"
        rpy="0 0 0" />
      <mass
        value="0.0098175" />
      <inertia
        ixx="1.5544E-06"
        ixy="1.7922E-24"
        ixz="8.8233E-24"
        iyy="1.5544E-06"
        iyz="3.4466E-26"
        izz="3.068E-06" />
    </inertial>
    <visual>
      <origin
        xyz="0 0 0"
        rpy="0 0 0" />
      <geometry>
        <mesh
          filename="package://hero_description/meshes/base_link.STL" />
      </geometry>
      <material
        name="">
        <color
          rgba="1 1 1 1" />
      </material>
    </visual>
    <collision>
      <origin
        xyz="0 0 0"
        rpy="0 0 0" />
      <geometry>
        <mesh
          filename="package://hero_description/meshes/base_link.STL" />
      </geometry>
    </collision>
  </link>
  <link
    name="yaw_link">
    <inertial>
      <origin
        xyz="-0.0051488 -0.031475 0.045253"
        rpy="0 0 0" />
      <mass
        value="0.93174" />
      <inertia
        ixx="0.001031"
        ixy="-4.9461E-07"
        ixz="8.554E-05"
        iyy="0.0011551"
        iyz="-2.2638E-07"
        izz="0.00081818" />
    </inertial>
    <visual>
      <origin
        xyz="0 0 0"
        rpy="0 0 0" />
      <geometry>
        <mesh
          filename="package://hero_description/meshes/yaw_link.STL" />
      </geometry>
      <material
        name="">
        <color
          rgba="0.75294 0.75294 0.75294 1" />
      </material>
    </visual>
    <collision>
      <origin
        xyz="0 0 0"
        rpy="0 0 0" />
      <geometry>
        <mesh
          filename="package://hero_description/meshes/yaw_link.STL" />
      </geometry>
    </collision>
  </link>
  <joint
    name="yaw_joint"
    type="continuous">
    <origin
      xyz="0 0 0"
      rpy="0 0 0" />
    <parent
      link="base_link" />
    <child
      link="yaw_link" />
    <axis
      xyz="0 0 1" />
  </joint>
  <link
    name="pitch_link">
    <inertial>
      <origin
        xyz="0.0034066 -0.001299 0.03678"
        rpy="0 0 0" />
      <mass
        value="1.2416" />
      <inertia
        ixx="0.0011211"
        ixy="-1.2138E-06"
        ixz="-0.00010276"
        iyy="0.0011238"
        iyz="-4.8565E-07"
        izz="0.001474" />
    </inertial>
    <visual>
      <origin
        xyz="0 0 0"
        rpy="0 0 0" />
      <geometry>
        <mesh
          filename="package://hero_description/meshes/pitch_link.STL" />
      </geometry>
      <material
        name="">
        <color
          rgba="1 1 1 1" />
      </material>
    </visual>
    <collision>
      <origin
        xyz="0 0 0"
        rpy="0 0 0" />
      <geometry>
        <mesh
          filename="package://hero_description/meshes/pitch_link.STL" />
      </geometry>
    </collision>
  </link>
  <joint
    name="pitch_joint"
    type="revolute">
    <origin
      xyz="0 0 0.168"
      rpy="0 0 0" />
    <parent
      link="yaw_link" />
    <child
      link="pitch_link" />
    <axis
      xyz="0 -1 0" />
    <limit
      lower="-0.5"
      upper="0.5"
      effort="0"
      velocity="0" />
  </joint>
  <link
    name="imu_link">
    <inertial>
      <origin
        xyz="1.3832E-08 -1.3393E-08 -0.0077319"
        rpy="0 0 0" />
      <mass
        value="0.020179" />
      <inertia
        ixx="2.5208E-06"
        ixy="3.9029E-09"
        ixz="1.4638E-12"
        iyy="2.8593E-06"
        iyz="-8.0874E-13"
        izz="4.5984E-06" />
    </inertial>
    <visual>
      <origin
        xyz="0 0 0"
        rpy="0 0 0" />
      <geometry>
        <mesh
          filename="package://hero_description/meshes/imu_link.STL" />
      </geometry>
      <material
        name="">
        <color
          rgba="1 1 1 1" />
      </material>
    </visual>
    <collision>
      <origin
        xyz="0 0 0"
        rpy="0 0 0" />
      <geometry>
        <mesh
          filename="package://hero_description/meshes/imu_link.STL" />
      </geometry>
    </collision>
  </link>
  <joint
    name="imu_joint"
    type="fixed">
    <origin
      xyz="-0.0501 -0.04935 0.07571"
      rpy="0 0 0" />
    <parent
      link="pitch_link" />
    <child
      link="imu_link" />
    <axis
      xyz="0 0 0" />
  </joint>
  <link
    name="camera_link">
    <inertial>
      <origin
        xyz="-0.044498 -2.6789E-05 0.00073584"
        rpy="0 0 0" />
      <mass
        value="0.064885" />
      <inertia
        ixx="7.9965E-06"
        ixy="-3.1555E-08"
        ixz="2.2346E-06"
        iyy="5.4721E-05"
        iyz="-7.2542E-09"
        izz="5.4499E-05" />
    </inertial>
    <visual>
      <origin
        xyz="0 0 0"
        rpy="0 0 0" />
      <geometry>
        <mesh
          filename="package://hero_description/meshes/camera_link.STL" />
      </geometry>
      <material
        name="">
        <color
          rgba="1 1 1 1" />
      </material>
    </visual>
    <collision>
      <origin
        xyz="0 0 0"
        rpy="0 0 0" />
      <geometry>
        <mesh
          filename="package://hero_description/meshes/camera_link.STL" />
      </geometry>
    </collision>
  </link>
  <joint
    name="camera_joint"
    type="fixed">
    <origin
      xyz="0.11853 0.053 0.10525"
      rpy="0 0 0" />
    <parent
      link="pitch_link" />
    <child
      link="camera_link" />
    <axis
      xyz="0 0 0" />
  </joint>
  <link
    name="camera_optical_link">
    <inertial>
      <origin
        xyz="1.0246E-12 -1.0246E-12 0.0005"
        rpy="0 0 0" />
      <mass
        value="7.0686E-06" />
      <inertia
        ixx="4.5651E-12"
        ixy="-2.4234E-28"
        ixz="-1.3388E-27"
        iyy="4.5651E-12"
        iyz="1.0046E-26"
        izz="7.9522E-12" />
    </inertial>
    <visual>
      <origin
        xyz="0 0 0"
        rpy="0 0 0" />
      <geometry>
        <mesh
          filename="package://hero_description/meshes/camera_optical_link.STL" />
      </geometry>
      <material
        name="">
        <color
          rgba="1 1 1 1" />
      </material>
    </visual>
    <collision>
      <origin
        xyz="0 0 0"
        rpy="0 0 0" />
      <geometry>
        <mesh
          filename="package://hero_description/meshes/camera_optical_link.STL" />
      </geometry>
    </collision>
  </link>
  <joint
    name="camera_optical_joint"
    type="fixed">
    <origin
      xyz="0 0 0"
      rpy="-1.5708 0 -1.5708" />
    <parent
      link="camera_link" />
    <child
      link="camera_optical_link" />
    <axis
      xyz="0 0 0" />
  </joint>
  <link
    name="gimbal_odom">
    <inertial>
      <origin
        xyz="-1.8319E-15 -0.001 -1.6376E-15"
        rpy="0 0 0" />
      <mass
        value="0.0014137" />
      <inertia
        ixx="2.9771E-07"
        ixy="7.8458E-24"
        ixz="2.4772E-25"
        iyy="6.3617E-09"
        iyz="-3.8523E-23"
        izz="2.9771E-07" />
    </inertial>
    <visual>
      <origin
        xyz="0 0 0"
        rpy="0 0 0" />
      <geometry>
        <mesh
          filename="package://hero_description/meshes/odom_link.STL" />
      </geometry>
      <material
        name="">
        <color
          rgba="1 1 1 1" />
      </material>
    </visual>
    <collision>
      <origin
        xyz="0 0 0"
        rpy="0 0 0" />
      <geometry>
        <mesh
          filename="package://hero_description/meshes/odom_link.STL" />
      </geometry>
    </collision>
  </link>
  <joint
    name="odom_joint"
    type="fixed">
    <origin
      xyz="0 0 0.168"
      rpy="0 0 0" />
    <parent
      link="base_link" />
    <child
      link="gimbal_odom" />
    <axis
      xyz="0 0 0" />
  </joint>
</robot>
